<robot name="upper_body">
  <joint name="shoulder_right_axis0" type="revolute">
    <parent link="torso" />
    <child link="shoulder_right_link1" />
    <origin rpy="0 0 0" xyz="-0.21017  0       0.69947" />
    <axis xyz="0.97437  0      -0.22495" />
    <limit effort="1.0" lower="-3.14159265359" upper="3.14159265359" velocity="10.0" />
  </joint>
  <joint name="shoulder_right_axis1" type="revolute">
    <parent link="shoulder_right_link1" />
    <child link="shoulder_right_link2" />
    <origin rpy="0 0 0" xyz="0 0 0" />
    <axis xyz="0 -1  0" />
    <limit effort="1.0" lower="-3.14159265359" upper="3.14159265359" velocity="10.0" />
  </joint>
  <joint name="shoulder_right_axis2" type="revolute">
    <parent link="shoulder_right_link2" />
    <child link="upperarm_right" />
    <origin rpy="0 0 0" xyz="0 0 0" />
    <axis xyz="-0.22495  0      -0.97437" />
    <limit effort="1.0" lower="-3.14159265359" upper="3.14159265359" velocity="10.0" />
  </joint>
  <joint name="head_axis0" type="revolute">
    <parent link="torso" />
    <child link="head_link1" />
    <origin rpy="0 0 0" xyz="0      0      0.84075" />
    <axis xyz="1 0 0" />
    <limit effort="1.0" lower="-3.14159265359" upper="3.14159265359" velocity="10.0" />
  </joint>
  <joint name="head_axis1" type="revolute">
    <parent link="head_link1" />
    <child link="head_link2" />
    <origin rpy="0 0 0" xyz="0 0 0" />
    <axis xyz="0  0 -1" />
    <limit effort="1.0" lower="-3.14159265359" upper="3.14159265359" velocity="10.0" />
  </joint>
  <joint name="head_axis2" type="revolute">
    <parent link="head_link2" />
    <child link="head" />
    <origin rpy="0 0 0" xyz="0 0 0" />
    <axis xyz="0 1 0" />
    <limit effort="1.0" lower="-3.14159265359" upper="3.14159265359" velocity="10.0" />
  </joint>
  <joint name="wrist_right_axis0" type="revolute">
    <parent link="lowerarm_right" />
    <child link="wrist_right_link1" />
    <origin rpy="0 0 0" xyz="-0.00616  0      -0.21039" />
    <axis xyz="1 0 0" />
    <limit effort="1.0" lower="-3.14159265359" upper="3.14159265359" velocity="10.0" />
  </joint>
  <joint name="wrist_right_axis1" type="revolute">
    <parent link="wrist_right_link1" />
    <child link="wrist_right_link2" />
    <origin rpy="0 0 0" xyz="0 0 0" />
    <axis xyz="0 -1  0" />
    <limit effort="1.0" lower="-3.14159265359" upper="3.14159265359" velocity="10.0" />
  </joint>
  <joint name="wrist_right_axis2" type="revolute">
    <parent link="wrist_right_link2" />
    <child link="hand_right" />
    <origin rpy="0 0 0" xyz="0 0 0" />
    <axis xyz="0  0 -1" />
    <limit effort="1.0" lower="-3.14159265359" upper="3.14159265359" velocity="10.0" />
  </joint>
  <joint name="wrist_left_axis0" type="revolute">
    <parent link="lowerarm_left" />
    <child link="wrist_left_link1" />
    <origin rpy="0 0 0" xyz="-0.00073  0      -0.21039" />
    <axis xyz="1 0 0" />
    <limit effort="1.0" lower="-3.14159265359" upper="3.14159265359" velocity="10.0" />
  </joint>
  <joint name="wrist_left_axis1" type="revolute">
    <parent link="wrist_left_link1" />
    <child link="wrist_left_link2" />
    <origin rpy="0 0 0" xyz="0 0 0" />
    <axis xyz="0 1 0" />
    <limit effort="1.0" lower="-3.14159265359" upper="3.14159265359" velocity="10.0" />
  </joint>
  <joint name="wrist_left_axis2" type="revolute">
    <parent link="wrist_left_link2" />
    <child link="hand_left" />
    <origin rpy="0 0 0" xyz="0 0 0" />
    <axis xyz="0 0 1" />
    <limit effort="1.0" lower="-3.14159265359" upper="3.14159265359" velocity="10.0" />
  </joint>
  <joint name="shoulder_left_axis0" type="revolute">
    <parent link="torso" />
    <child link="shoulder_left_link1" />
    <origin rpy="0 0 0" xyz="0.21017 0      0.69947" />
    <axis xyz="0.97437 0      0.22495" />
    <limit effort="1.0" lower="-3.14159265359" upper="3.14159265359" velocity="10.0" />
  </joint>
  <joint name="shoulder_left_axis1" type="revolute">
    <parent link="shoulder_left_link1" />
    <child link="shoulder_left_link2" />
    <origin rpy="0 0 0" xyz="0 0 0" />
    <axis xyz="0 1 0" />
    <limit effort="1.0" lower="-3.14159265359" upper="3.14159265359" velocity="10.0" />
  </joint>
  <joint name="shoulder_left_axis2" type="revolute">
    <parent link="shoulder_left_link2" />
    <child link="upperarm_left" />
    <origin rpy="0 0 0" xyz="0 0 0" />
    <axis xyz="-0.22495  0       0.97437" />
    <limit effort="1.0" lower="-3.14159265359" upper="3.14159265359" velocity="10.0" />
  </joint>
  <joint name="elbow_right_axis1" type="revolute">
    <parent link="elbow_right" />
    <child link="lowerarm_right" />
    <origin rpy="0 0 0" xyz="0.00042  0      -0.09" />
    <axis xyz="1 0 0" />
    <limit effort="1.0" lower="-1.57079632679" upper="0.0" velocity="10.0" />
  </joint>
  <joint name="elbow_right_axis0" type="revolute">
    <parent link="upperarm_right" />
    <child link="elbow_right" />
    <origin rpy="0 0 0" xyz="-0.00106  0      -0.31208" />
    <axis xyz="-1  0  0" />
    <limit effort="1.0" lower="0.0" upper="1.2217304764" velocity="10.0" />
  </joint>
  <joint name="elbow_left_axis0" type="revolute">
    <parent link="upperarm_left" />
    <child link="elbow_left" />
    <origin rpy="0 0 0" xyz="0.00906  0      -0.31208" />
    <axis xyz="-1  0  0" />
    <limit effort="1.0" lower="0.0" upper="1.57079632679" velocity="10.0" />
  </joint>
  <joint name="elbow_left_axis1" type="revolute">
    <parent link="elbow_left" />
    <child link="lowerarm_left" />
    <origin rpy="0 0 0" xyz="-0.0015  0     -0.09" />
    <axis xyz="-1  0  0" />
    <limit effort="1.0" lower="0.0" upper="1.0471975512" velocity="10.0" />
  </joint>
  <link name="hand_right">
    <inertial>
      <mass value="0.7514923831884623" />
      <origin rpy="0 0 0" xyz="-0.00506  0.00106 -0.06163" />
      <inertia ixx="0.00329642178906037" ixy="0.0002152027426110002" ixz="0.00414519741777471" iyy="0.040151355516369454" iyz="5.779025691769195e-06" izz="0.03751229870240237" />
    </inertial>
    <collision name="hand_right_collision">
      <origin rpy="0 0 0" xyz="-0.00506  0.00106 -0.06163" />
      <geometry>
        <mesh filename="package://robots/upper_body/meshes/collisions/hand_right.stl" scale="0.001 0.001 0.001" />
      </geometry>
    </collision>
    <visual name="hand_right_visual">
      <origin rpy="0 0 0" xyz="-0.00506  0.00106 -0.06163" />
      <geometry>
        <mesh filename="package://robots/upper_body/meshes/visuals/hand_right.stl" scale="0.001 0.001 0.001" />
      </geometry>
    </visual>
  </link>
  <link name="lowerarm_right">
    <inertial>
      <mass value="0.5917876637421493" />
      <origin rpy="0 0 0" xyz="-0.00733 -0.00117 -0.11185" />
      <inertia ixx="0.025266093053321618" ixy="-0.00014339118944252453" ixz="0.02401182953031049" iyy="0.05347049319194963" iyz="0.00020339489462638876" izz="0.02883407069587139" />
    </inertial>
    <collision name="lowerarm_right_collision">
      <origin rpy="0 0 0" xyz="-0.00733 -0.00117 -0.11185" />
      <geometry>
        <mesh filename="package://robots/upper_body/meshes/collisions/lowerarm_right.stl" scale="0.001 0.001 0.001" />
      </geometry>
    </collision>
    <visual name="lowerarm_right_visual">
      <origin rpy="0 0 0" xyz="-0.00733 -0.00117 -0.11185" />
      <geometry>
        <mesh filename="package://robots/upper_body/meshes/visuals/lowerarm_right.stl" scale="0.001 0.001 0.001" />
      </geometry>
    </visual>
  </link>
  <link name="upperarm_left">
    <inertial>
      <mass value="0.6793810152872208" />
      <origin rpy="0 0 0" xyz="0.01104  0.00134 -0.18587" />
      <inertia ixx="0.18978590848989427" ixy="-0.00020381676007052703" ixz="-0.0771493215460898" iyy="0.22219285048351112" iyz="-0.00048014462260051406" izz="0.034641097561777544" />
    </inertial>
    <collision name="upperarm_left_collision">
      <origin rpy="0 0 0" xyz="0.01104  0.00134 -0.18587" />
      <geometry>
        <mesh filename="package://robots/upper_body/meshes/collisions/upperarm_left.stl" scale="0.001 0.001 0.001" />
      </geometry>
    </collision>
    <visual name="upperarm_left_visual">
      <origin rpy="0 0 0" xyz="0.01104  0.00134 -0.18587" />
      <geometry>
        <mesh filename="package://robots/upper_body/meshes/visuals/upperarm_left.stl" scale="0.001 0.001 0.001" />
      </geometry>
    </visual>
  </link>
  <link name="hand_left">
    <inertial>
      <mass value="0.7514925489985023" />
      <origin rpy="0 0 0" xyz="0.00506  0.00106 -0.06163" />
      <inertia ixx="0.003296422481405665" ixy="-0.000215224109805972" ixz="-0.004145710073447077" iyy="0.0401603001987594" iyz="5.779043768172425e-06" izz="0.03752124270591726" />
    </inertial>
    <collision name="hand_left_collision">
      <origin rpy="0 0 0" xyz="0.00506  0.00106 -0.06163" />
      <geometry>
        <mesh filename="package://robots/upper_body/meshes/collisions/hand_left.stl" scale="0.001 0.001 0.001" />
      </geometry>
    </collision>
    <visual name="hand_left_visual">
      <origin rpy="0 0 0" xyz="0.00506  0.00106 -0.06163" />
      <geometry>
        <mesh filename="package://robots/upper_body/meshes/visuals/hand_left.stl" scale="0.001 0.001 0.001" />
      </geometry>
    </visual>
  </link>
  <link name="lowerarm_left">
    <inertial>
      <mass value="0.4831137845041076" />
      <origin rpy="0 0 0" xyz="0.00049 -0.00129 -0.09306" />
      <inertia ixx="0.024158444781384562" ixy="0.00012820759060466918" ixz="-0.02159885035361162" iyy="0.04720250767947627" iyz="0.00019696815911384214" izz="0.02362176591875769" />
    </inertial>
    <collision name="lowerarm_left_collision">
      <origin rpy="0 0 0" xyz="0.00049 -0.00129 -0.09306" />
      <geometry>
        <mesh filename="package://robots/upper_body/meshes/collisions/lowerarm_left.stl" scale="0.001 0.001 0.001" />
      </geometry>
    </collision>
    <visual name="lowerarm_left_visual">
      <origin rpy="0 0 0" xyz="0.00049 -0.00129 -0.09306" />
      <geometry>
        <mesh filename="package://robots/upper_body/meshes/visuals/lowerarm_left.stl" scale="0.001 0.001 0.001" />
      </geometry>
    </visual>
  </link>
  <link name="upperarm_right">
    <inertial>
      <mass value="0.6628658945679491" />
      <origin rpy="0 0 0" xyz="-0.01115  0.00138 -0.17499" />
      <inertia ixx="0.18968787262556008" ixy="0.00020382119259871294" ixz="0.07687427496899825" iyy="0.22131713020188437" iyz="-0.00048015612471741167" izz="0.033863143154471184" />
    </inertial>
    <collision name="upperarm_right_collision">
      <origin rpy="0 0 0" xyz="-0.01115  0.00138 -0.17499" />
      <geometry>
        <mesh filename="package://robots/upper_body/meshes/collisions/upperarm_right.stl" scale="0.001 0.001 0.001" />
      </geometry>
    </collision>
    <visual name="upperarm_right_visual">
      <origin rpy="0 0 0" xyz="-0.01115  0.00138 -0.17499" />
      <geometry>
        <mesh filename="package://robots/upper_body/meshes/visuals/upperarm_right.stl" scale="0.001 0.001 0.001" />
      </geometry>
    </visual>
  </link>
  <link name="head">
    <inertial>
      <mass value="2.1598514080281315" />
      <origin rpy="0 0 0" xyz="-0.0002  -0.01814  0.1507" />
      <inertia ixx="2.1559773436970113" ixy="2.323405580889926e-05" ixz="0.0004164361828475648" iyy="2.1576901383913416" iyz="0.03738915961197302" izz="0.02811964967375591" />
    </inertial>
    <collision name="head_collision">
      <origin rpy="0 0 0" xyz="-0.0002  -0.01814  0.1507" />
      <geometry>
        <mesh filename="package://robots/upper_body/meshes/collisions/head.stl" scale="0.001 0.001 0.001" />
      </geometry>
    </collision>
    <visual name="head_visual">
      <origin rpy="0 0 0" xyz="-0.0002  -0.01814  0.1507" />
      <geometry>
        <mesh filename="package://robots/upper_body/meshes/visuals/head.stl" scale="0.001 0.001 0.001" />
      </geometry>
    </visual>
  </link>
  <link name="torso">
    <inertial>
      <mass value="25.160471303342216" />
      <origin rpy="0 0 0" xyz="0.00776 0.00282 0.62658" />
      <inertia ixx="10.398585859477636" ixy="0.00015013373897767912" ixz="-0.10586365499644151" iyy="10.58255768903264" iyz="-0.05807739632925058" izz="0.4658890640245697" />
    </inertial>
    <collision name="torso_collision">
      <origin rpy="0 0 0" xyz="0.00776 0.00282 0.62658" />
      <geometry>
        <mesh filename="package://robots/upper_body/meshes/collisions/torso.stl" scale="0.001 0.001 0.001" />
      </geometry>
    </collision>
    <visual name="torso_visual">
      <origin rpy="0 0 0" xyz="0.00776 0.00282 0.62658" />
      <geometry>
        <mesh filename="package://robots/upper_body/meshes/visuals/torso.stl" scale="0.001 0.001 0.001" />
      </geometry>
    </visual>
  </link>
  <link name="elbow_right">
    <inertial>
      <mass value="0.035913480602683866" />
      <origin rpy="0 0 0" xyz="-0.00474  0.03025 -0.04463" />
      <inertia ixx="0.004274453667256835" ixy="0.00023607548638453937" ixz="0.002658593224303575" iyy="0.005909490039237715" iyz="-0.0003724752910205753" izz="0.0017216986311418606" />
    </inertial>
    <collision name="elbow_right_collision">
      <origin rpy="0 0 0" xyz="-0.00474  0.03025 -0.04463" />
      <geometry>
        <mesh filename="package://robots/upper_body/meshes/collisions/elbow_right.stl" scale="0.001 0.001 0.001" />
      </geometry>
    </collision>
    <visual name="elbow_right_visual">
      <origin rpy="0 0 0" xyz="-0.00474  0.03025 -0.04463" />
      <geometry>
        <mesh filename="package://robots/upper_body/meshes/visuals/elbow_right.stl" scale="0.001 0.001 0.001" />
      </geometry>
    </visual>
  </link>
  <link name="shoulder_right_link1">
    <inertial>
      <mass value="0.09036362653441246" />
      <origin rpy="0 0 0" xyz="0 0 0" />
      <inertia ixx="0.04421931675263708" ixy="3.626265954181918e-18" ixz="0.01328454638864534" iyy="0.04821095418145326" iyz="-1.2045919817182948e-17" izz="0.003998729023415919" />
    </inertial>
    <collision name="shoulder_right_link1_collision">
      <origin rpy="0 0 0" xyz="0 0 0" />
      <geometry>
        <mesh filename="package://robots/upper_body/meshes/collisions/shoulder_right_link1.stl" scale="0.001 0.001 0.001" />
      </geometry>
    </collision>
    <visual name="shoulder_right_link1_visual">
      <origin rpy="0 0 0" xyz="0 0 0" />
      <geometry>
        <mesh filename="package://robots/upper_body/meshes/visuals/shoulder_right_link1.stl" scale="0.001 0.001 0.001" />
      </geometry>
    </visual>
  </link>
  <link name="shoulder_right_link2">
    <inertial>
      <mass value="0.007113171768014983" />
      <origin rpy="0 0 0" xyz="0 0 0" />
      <inertia ixx="0.0034803651538984483" ixy="2.808517307606451e-19" ixz="0.0010457223104764577" iyy="0.0037945756803650283" iyz="-9.325873406851316e-19" izz="0.0003143130585953205" />
    </inertial>
    <collision name="shoulder_right_link2_collision">
      <origin rpy="0 0 0" xyz="0 0 0" />
      <geometry>
        <mesh filename="package://robots/upper_body/meshes/collisions/shoulder_right_link2.stl" scale="0.001 0.001 0.001" />
      </geometry>
    </collision>
    <visual name="shoulder_right_link2_visual">
      <origin rpy="0 0 0" xyz="0 0 0" />
      <geometry>
        <mesh filename="package://robots/upper_body/meshes/visuals/shoulder_right_link2.stl" scale="0.001 0.001 0.001" />
      </geometry>
    </visual>
  </link>
  <link name="wrist_right_link1">
    <inertial>
      <mass value="0.03806502884740437" />
      <origin rpy="0 0 0" xyz="0 0 0" />
      <inertia ixx="0.00028979287111819324" ixy="1.061650767297806e-18" ixz="0.0007185410043660903" iyy="0.0020817946848411925" iyz="-4.250072516143178e-19" izz="0.0017936804814951703" />
    </inertial>
    <collision name="wrist_right_link1_collision">
      <origin rpy="0 0 0" xyz="0 0 0" />
      <geometry>
        <mesh filename="package://robots/upper_body/meshes/collisions/wrist_right_link1.stl" scale="0.001 0.001 0.001" />
      </geometry>
    </collision>
    <visual name="wrist_right_link1_visual">
      <origin rpy="0 0 0" xyz="0 0 0" />
      <geometry>
        <mesh filename="package://robots/upper_body/meshes/visuals/wrist_right_link1.stl" scale="0.001 0.001 0.001" />
      </geometry>
    </visual>
  </link>
  <link name="wrist_right_link2">
    <inertial>
      <mass value="0.002996372533177606" />
      <origin rpy="0 0 0" xyz="0 0 0" />
      <inertia ixx="2.2703814321141537e-05" ixy="8.278967789099312e-20" ixz="5.656153678683516e-05" iyy="0.0001637651815821358" iyz="-3.315490243460673e-20" izz="0.000141085637878513" />
    </inertial>
    <collision name="wrist_right_link2_collision">
      <origin rpy="0 0 0" xyz="0 0 0" />
      <geometry>
        <mesh filename="package://robots/upper_body/meshes/collisions/wrist_right_link2.stl" scale="0.001 0.001 0.001" />
      </geometry>
    </collision>
    <visual name="wrist_right_link2_visual">
      <origin rpy="0 0 0" xyz="0 0 0" />
      <geometry>
        <mesh filename="package://robots/upper_body/meshes/visuals/wrist_right_link2.stl" scale="0.001 0.001 0.001" />
      </geometry>
    </visual>
  </link>
  <link name="elbow_left">
    <inertial>
      <mass value="0.03591352060165305" />
      <origin rpy="0 0 0" xyz="-0.00325  0.03025 -0.04463" />
      <inertia ixx="0.004274458918966475" ixy="-0.00023607544149196254" ixz="-0.002658629464100515" iyy="0.0059095370580604595" iyz="-0.000372475167922204" izz="0.0017217402510529421" />
    </inertial>
    <collision name="elbow_left_collision">
      <origin rpy="0 0 0" xyz="-0.00325  0.03025 -0.04463" />
      <geometry>
        <mesh filename="package://robots/upper_body/meshes/collisions/elbow_left.stl" scale="0.001 0.001 0.001" />
      </geometry>
    </collision>
    <visual name="elbow_left_visual">
      <origin rpy="0 0 0" xyz="-0.00325  0.03025 -0.04463" />
      <geometry>
        <mesh filename="package://robots/upper_body/meshes/visuals/elbow_left.stl" scale="0.001 0.001 0.001" />
      </geometry>
    </visual>
  </link>
  <link name="shoulder_left_link1">
    <inertial>
      <mass value="0.09036362653441248" />
      <origin rpy="0 0 0" xyz="0 0 0" />
      <inertia ixx="0.044219316752637086" ixy="-3.6290415117434806e-18" ixz="-0.013284546388645343" iyy="0.04821095418145326" iyz="-1.2079226507921704e-17" izz="0.003998729023415921" />
    </inertial>
    <collision name="shoulder_left_link1_collision">
      <origin rpy="0 0 0" xyz="0 0 0" />
      <geometry>
        <mesh filename="package://robots/upper_body/meshes/collisions/shoulder_left_link1.stl" scale="0.001 0.001 0.001" />
      </geometry>
    </collision>
    <visual name="shoulder_left_link1_visual">
      <origin rpy="0 0 0" xyz="0 0 0" />
      <geometry>
        <mesh filename="package://robots/upper_body/meshes/visuals/shoulder_left_link1.stl" scale="0.001 0.001 0.001" />
      </geometry>
    </visual>
  </link>
  <link name="shoulder_left_link2">
    <inertial>
      <mass value="0.007113171768014981" />
      <origin rpy="0 0 0" xyz="0 0 0" />
      <inertia ixx="0.003480365153898447" ixy="-2.8206603719382882e-19" ixz="-0.0010457223104764577" iyy="0.003794575680365027" iyz="-9.370976217226712e-19" izz="0.0003143130585953206" />
    </inertial>
    <collision name="shoulder_left_link2_collision">
      <origin rpy="0 0 0" xyz="0 0 0" />
      <geometry>
        <mesh filename="package://robots/upper_body/meshes/collisions/shoulder_left_link2.stl" scale="0.001 0.001 0.001" />
      </geometry>
    </collision>
    <visual name="shoulder_left_link2_visual">
      <origin rpy="0 0 0" xyz="0 0 0" />
      <geometry>
        <mesh filename="package://robots/upper_body/meshes/visuals/shoulder_left_link2.stl" scale="0.001 0.001 0.001" />
      </geometry>
    </visual>
  </link>
  <link name="wrist_left_link1">
    <inertial>
      <mass value="0.03806502884740436" />
      <origin rpy="0 0 0" xyz="0 0 0" />
      <inertia ixx="0.00028979287111817464" ixy="-8.971989817752046e-19" ixz="-0.0007186296796101484" iyy="0.002082237014513603" iyz="-3.590877595271991e-19" izz="0.0017941228111675988" />
    </inertial>
    <collision name="wrist_left_link1_collision">
      <origin rpy="0 0 0" xyz="0 0 0" />
      <geometry>
        <mesh filename="package://robots/upper_body/meshes/collisions/wrist_left_link1.stl" scale="0.001 0.001 0.001" />
      </geometry>
    </collision>
    <visual name="wrist_left_link1_visual">
      <origin rpy="0 0 0" xyz="0 0 0" />
      <geometry>
        <mesh filename="package://robots/upper_body/meshes/visuals/wrist_left_link1.stl" scale="0.001 0.001 0.001" />
      </geometry>
    </visual>
  </link>
  <link name="wrist_left_link2">
    <inertial>
      <mass value="0.002996372533177606" />
      <origin rpy="0 0 0" xyz="0 0 0" />
      <inertia ixx="2.2703814321140076e-05" ixy="-7.034303695085953e-20" ixz="-5.656851705386013e-05" iyy="0.00016380000053594067" iyz="-2.816757244117341e-20" izz="0.00014112045683231935" />
    </inertial>
    <collision name="wrist_left_link2_collision">
      <origin rpy="0 0 0" xyz="0 0 0" />
      <geometry>
        <mesh filename="package://robots/upper_body/meshes/collisions/wrist_left_link2.stl" scale="0.001 0.001 0.001" />
      </geometry>
    </collision>
    <visual name="wrist_left_link2_visual">
      <origin rpy="0 0 0" xyz="0 0 0" />
      <geometry>
        <mesh filename="package://robots/upper_body/meshes/visuals/wrist_left_link2.stl" scale="0.001 0.001 0.001" />
      </geometry>
    </visual>
  </link>
  <link name="head_link1">
    <inertial>
      <mass value="0.03806502884740436" />
      <origin rpy="0 0 0" xyz="0 0 0" />
      <inertia ixx="0.026908346370427178" ixy="-2.168404344971009e-22" ixz="-2.4424906541753445e-19" iyy="0.026908346370427178" iyz="5.601075159233915e-18" izz="1.6786677721705307e-06" />
    </inertial>
    <collision name="head_link1_collision">
      <origin rpy="0 0 0" xyz="0 0 0" />
      <geometry>
        <mesh filename="package://robots/upper_body/meshes/collisions/head_link1.stl" scale="0.001 0.001 0.001" />
      </geometry>
    </collision>
    <visual name="head_link1_visual">
      <origin rpy="0 0 0" xyz="0 0 0" />
      <geometry>
        <mesh filename="package://robots/upper_body/meshes/visuals/head_link1.stl" scale="0.001 0.001 0.001" />
      </geometry>
    </visual>
  </link>
  <link name="head_link2">
    <inertial>
      <mass value="0.002996372533177606" />
      <origin rpy="0 0 0" xyz="0 0 0" />
      <inertia ixx="0.002118041844878994" ixy="3.404394821608228e-24" ixz="-1.78481526433294e-20" iyy="0.002118041844878994" iyz="4.440892098500626e-19" izz="2.427061751873877e-08" />
    </inertial>
    <collision name="head_link2_collision">
      <origin rpy="0 0 0" xyz="0 0 0" />
      <geometry>
        <mesh filename="package://robots/upper_body/meshes/collisions/head_link2.stl" scale="0.001 0.001 0.001" />
      </geometry>
    </collision>
    <visual name="head_link2_visual">
      <origin rpy="0 0 0" xyz="0 0 0" />
      <geometry>
        <mesh filename="package://robots/upper_body/meshes/visuals/head_link2.stl" scale="0.001 0.001 0.001" />
      </geometry>
    </visual>
  </link>

  <!-- Connect to world -->
  <link name="world" />
  <joint name="world_joint" type="fixed">
          <parent link="world" />
          <child link = "torso" />
          <origin xyz="0.0 0.0 0.0" rpy="0.0 0.0 0.0" />
  </joint>
</robot>
